Workbook
Name _Hlk187854711: Kalaburagi!$B$121

Sheet ABSTRACT
A1: Kalaburgi Disrtict Taluk Wise Abstract for the Month of JUN- 2026
A2: Quantity of Bio-medical Waste Received All in Kg/month | G2: General Waste | H2: Total Qty in kg/month
A3: S. No | B3: Place | C3: Yellow Category | D3: Red Category | E3: Blue Category | F3: White Category
A4: 1 | B4: All Govt Hospitals | C4: =GOVT.HOSPITALS!E198 -> 930 | D4: =GOVT.HOSPITALS!F198 -> 320 | E4: =GOVT.HOSPITALS!G198 -> 453 | F4: =GOVT.HOSPITALS!H198 -> 9.46 | G4: =GOVT.HOSPITALS!I198 -> 0 | H4: =GOVT.HOSPITALS!J198 -> 1712.46
A5: 2 | B5: Jewargi Taluk | C5: =Jewargi!F82 -> 218 | D5: =Jewargi!G82 -> 150 | E5: =Jewargi!H82 -> 137 | F5: =Jewargi!I82 -> 3.25 | G5: =Jewargi!J82 -> 75 | H5: =Jewargi!K82 -> 583.25
A6: 3 | B6: Sedam Taluk | C6: =Sedam!F76 -> 241 | D6: =Sedam!G76 -> 128 | E6: =Sedam!H76 -> 159 | F6: =Sedam!I76 -> 1.98 | G6: =Sedam!J76 -> 98 | H6: =Sedam!K76 -> 627.98
A7: 4 | B7: Chittapur Taluk | C7: =Chittapur!F86 -> 222 | D7: =Chittapur!G86 -> 117 | E7: =Chittapur!H86 -> 119 | F7: =Chittapur!I86 -> 1.54 | G7: =Chittapur!J86 -> 53 | H7: =Chittapur!K86 -> 512.54
A8: 5 | B8: Kalaburagi Taluk | C8: =Kalaburagi!F354 -> 4908 | D8: =Kalaburagi!G354 -> 3109 | E8: =Kalaburagi!H354 -> 1105 | F8: =Kalaburagi!I354 -> 85.77 | G8: =Kalaburagi!J354 -> 730 | H8: =Kalaburagi!K354 -> 9937.77
B9: TOTAL | C9: =SUM(C4:C8) -> 6519 | D9: =SUM(D4:D8) -> 3824 | E9: =SUM(E4:E8) -> 1973 | F9: =SUM(F4:F8) -> 102 | G9: =SUM(G4:G8) -> 956 | H9: =SUM(H4:H8) -> 13374
A11: Total No.Of HCF'S Coverd by CBMWTF | F11: =G17 -> 772
A12: S. No | B12: Place | C12: Government Hospital | D12: Private Hospital | E12: Ayush | F12: Veterinary | G12: No of HCF'S
A13: 1 | B13: Jewargi Taluk | C13: 48 | D13: =Jewargi!D93 -> 77 | E13: 0 | F13: 2 | G13: =SUM(C13:F13) -> 127
A14: 2 | B14: Sedam Taluk | C14: 45 | D14: =Sedam!D87 -> 71 | E14: 0 | F14: 0 | G14: =SUM(C14:F14) -> 116
A15: 3 | B15: Chittapur Taluk | C15: 60 | D15: =Chittapur!D97 -> 81 | E15: 0 | F15: 0 | G15: =SUM(C15:F15) -> 141
A16: 4 | B16: Kalaburagi Taluk | C16: 39 | D16: =Kalaburagi!D365 -> 349 | E16: 0 | F16: 0 | G16: =SUM(C16:F16) -> 388
B17: TOTAL | C17: =SUM(C13:C16) -> 192 | D17: =SUM(D13:D16) -> 578 | E17: =SUM(E13:E16) -> 0 | F17: =SUM(F13:F16) -> 2 | G17: =SUM(C17:F17) -> 772
A20: Total No.Of Bedded Hospital, Clinic, Lab & Blood Bank Coverd by CBMWTF | I20: 771
A21: S. No | B21: Place | C21: Bedded Hospital | F21: Non Bedded Govt Hospitals | I21: Non Bedded Private Hospitals | N21: No of HCF'S
C22: Government | D22: Ayush | E22: Private | F22: SC-AAM | G22: UPHC/Namma Clinics | H22: Veterinary | I22: Clinic | J22: Dental | K22: Blood Bank | L22: Laboratory | M22: Scanning Center + X-Ray
A23: 1 | B23: Jewargi Taluk | C23: =16 -> 16 | D23: 0 | E23: =Jewargi!D87 -> 13 | F23: 31 | G23: =1 -> 1 | H23: 2 | I23: =Jewargi!D88 -> 45 | J23: =Jewargi!D89 -> 5 | K23: =Jewargi!D92 -> 0 | L23: =Jewargi!D90 -> 13 | M23: =Jewargi!D91 -> 1 | N23: =SUM(C23:M23) -> 127
A24: 2 | B24: Sedam Taluk | C24: =11 -> 11 | D24: 0 | E24: =Sedam!D81 -> 13 | F24: 33 | G24: 1 | I24: =Sedam!D82 -> 48 | J24: =Sedam!D83 -> 4 | K24: =Sedam!D86 -> 0 | L24: =Sedam!D84 -> 6 | M24: =Sedam!D85 -> 0 | N24: =SUM(C24:M24) -> 116
A25: 3 | B25: Chittapur Taluk | C25: =20 -> 20 | D25: 0 | E25: =Chittapur!D91 -> 7 | F25: 37 | G25: 3 | I25: =Chittapur!D92 -> 59 | J25: =Chittapur!D93 -> 6 | K25: =Chittapur!D96 -> 0 | L25: =Chittapur!D94 -> 9 | M25: =Chittapur!D95 -> 0 | N25: =SUM(C25:M25) -> 141
A26: 4 | B26: Kalaburagi Taluk | C26: 6 | D26: 0 | E26: =Kalaburagi!D359 -> 170 | F26: 26 | G26: =5+2 -> 7 | I26: =Kalaburagi!D360 -> 98 | J26: =Kalaburagi!D361 -> 36 | K26: =Kalaburagi!D364 -> 3 | L26: =Kalaburagi!D362 -> 35 | M26: =Kalaburagi!D363 -> 7 | N26: =SUM(C26:M26) -> 388
B27: TOTAL | C27: =SUM(C23:C26) -> 53 | D27: =SUM(D23:D26) -> 0 | E27: =SUM(E23:E26) -> 203 | F27: =SUM(F23:F26) -> 127 | G27: =SUM(G23:G26) -> 12 | H27: =SUM(H23:H26) -> 2 | I27: =SUM(I23:I26) -> 250 | J27: =SUM(J23:J26) -> 51 | ... N27: =SUM(N23:N26) -> 772
B29: Total No Of Bed's Coverd by CBMWTF | D29: =C33 -> 5588
B30: Number Of Bed's | F30: M/s. Parisara Associates, Yadgir (CBMWTF)
B31: Govt Hospital | C31: =GOVT.HOSPITALS!C198 -> 804
B32: Private Hospital | C32: =Jewargi!D82+Sedam!D76+Chittapur!D86+Kalaburagi!D354 -> 4784
B33: TOTAL | C33: =SUM(C31:C32) -> 5588

Sheet GOVT.HOSPITALS
A1: Collection of Bio-Medical Waste from All Govt. Hospitals, Kalaburagi Dist. in Category wise for the month of JUN-2026
A2: Sr.No | B2: Name Of Hospitals | C2: Quantity of Bio-medical Waste Received All in Kg/month | I2: GENERAL | J2: Total Qty in kg/month
C3: BED'S | D3: PLACE | E3: YELLOW | F3: RED | G3: BLUE | H3: WHITE
A4: 1 | B4: Genaral Hospital | C4: 100 | D4: Chittapur | E4: 65 | F4: 30 | G4: 29 | H4: 0.8 | J4: =SUM(E4:I4) -> 124.8
A5: 2 | B5: Community Health Centre | C5: 30 | D5: Gundugurti | E5: 29 | F5: 6 | G5: 12 | H5: 0.4 | J5: =SUM(E5:I5) -> 47.4
A6: 3 | B6: Community Health Centre | C6: 30 | D6: Hebbal | E6: 22 | F6: 10 | G6: 11 | H6: 0.3 | J6: =SUM(E6:I6) -> 43.3
A7: 4 | B7: Community Health Centre | C7: 30 | D7: Kalagi | E7: 26 | F7: 8 | G7: 13 | H7: 0.5 | J7: =SUM(E7:I7) -> 47.5
A8: 5 | B8: Community Health Centre | C8: 30 | D8: Shahbad | E8: 27 | F8: 10 | G8: 14 | H8: 0.6 | J8: =SUM(E8:I8) -> 51.6
A9: 6 | B9: Community Health Centre | C9: 30 | D9: Wadi | E9: 28 | F9: 5 | G9: 12 | H9: 0.5 | J9: =SUM(E9:I9) -> 45.5
A10: 7 | B10: Primary Health Centre | C10: 6 | D10: Alhalli | E10: 5 | F10: 2 | G10: 4 | H10: 0.01 | J10: =SUM(E10:I10) -> 11.01
A11: 8 | B11: Primary Health Centre | C11: 6 | D11: Allur K | E11: 5 | F11: 3 | G11: 3 | H11: 0.01 | J11: =SUM(E11:I11) -> 11.01
A12: 9 | B12: Primary Health Centre | C12: 6 | D12: Arankal | E12: 6 | F12: 2 | G12: 2 | H12: 0.01 | J12: =SUM(E12:I12) -> 10.01
A13: 10 | B13: Primary Health Centre | C13: 6 | D13: Dandoti | E13: 4 | F13: 1 | G13: 3 | H13: 0.01 | J13: =SUM(E13:I13) -> 8.01
A14: 11 | B14: Primary Health Centre | C14: 6 | D14: Diggaon | E14: 5 | F14: 2 | G14: 5 | H14: 0.01 | J14: =SUM(E14:I14) -> 12.01
A15: 12 | B15: Primary Health Centre | C15: 6 | D15: Kal Hipparga | E15: 3 | F15: 2 | G15: 5 | H15: 0.01 | J15: =SUM(E15:I15) -> 10.01
... A34: 31 | B34: Primary Health Centre | C34: 6 | D34: Biryal. B | E34: 3 | F34: 1 | G34: 3 | H34: 0.01 | J34: =SUM(E34:I34) -> 7.01
A35: 32 | B35: Primary Health Centre | C35: 6 | D35: Ganwar | E35: 3 | F35: 2 | G35: 2 | J35: =SUM(E35:I35) -> 7
A36: 33 | B36: Primary Health Centre | C36: 6 | D36: Ijeri | E36: 5 | F36: 1 | G36: 3 | J36: =SUM(E36:I36) -> 9
A37: 34 | B37: Primary Health Centre | C37: 6 | D37: Jeratgi | E37: 4 | F37: 3 | G37: 4 | J37: =SUM(E37:I37) -> 11
A38: 35 | B38: Primary Health Centre | C38: 6 | D38: Koodi | E38: 5 | F38: 3 | G38: 3 | J38: =SUM(E38:I38) -> 11
A39: 36 | B39: Primary Health Centre | C39: 6 | D39: Malli | E39: 4 | F39: 2 | G39: 4 | J39: =SUM(E39:I39) -> 10
A40: 37 | B40: Primary Health Centre | C40: 6 | D40: Mandewal | E40: 5 | F40: 2 | G40: 4 | J40: =SUM(E40:I40) -> 11
A41: 38 | B41: Primary Health Centre | C41: 6 | D41: Naribol | E41: 4 | F41: 3 | G41: 3 | J41: =SUM(E41:I41) -> 10
A42: 39 | B42: Namma Clinic | C42: 0 | D42: Jewargi | E42: 1 | F42: 1 | G42: 1 | H42: 0.005 | J42: =SUM(E42:I42) -> 3.005
A43: 40 | B43: Primary Health Centre | C43: 6 | D43: Wadgera | E43: 5 | F43: 2 | G43: 2 | H43: 0.01 | J43: =SUM(E43:I43) -> 9.01
A44: 41 | B44: Genaral Hospital | C44: 100 | D44: Sedam | E44: 95 | F44: 25 | G44: 42 | H44: 0.9 | J44: =SUM(E44:I44) -> 162.9
A45: 42 | B45: Community Health Centre | C45: 30 | D45: Malkhed | E45: 31 | F45: 4 | G45: 12 | H45: 0.6 | J45: =SUM(E45:I45) -> 47.6
A46: 43 | B46: Primary Health Centre | C46: 30 | D46: Mudhol | E46: 23 | F46: 4 | G46: 10 | H46: 0.6 | J46: =SUM(E46:I46) -> 37.6
A47: 44 | B47: PRIMARY HEALTH CENTRE | C47: 6 | D47: Itkal | E47: 6 | F47: 3 | G47: 4 | H47: 0.01 | J47: =SUM(E47:I47) -> 13.01
A48: 45 | B48: PRIMARY HEALTH CENTRE | C48: 6 | D48: Khanagadda | E48: 5 | F48: 2 | G48: 5 | H48: 0.01 | J48: =SUM(E48:I48) -> 12.01
A49: 46 | B49: PRIMARY HEALTH CENTRE | C49: 6 | D49: Khanderayanapalli | E49: 6 | F49: 3 | G49: 4 | H49: 0.01 | J49: =SUM(E49:I49) -> 13.01
A50: 47 | B50: PRIMARY HEALTH CENTRE | C50: 6 | D50: Kodla | E50: 7 | F50: 2 | G50: 5 | J50: =SUM(E50:I50) -> 14
A51: 48 | B51: PRIMARY HEALTH CENTRE | C51: 6 | D51: Kolkunda | E51: 6 | F51: 2 | G51: 5 | H51: 0.01 | J51: =SUM(E51:I51) -> 13.01
A52: 49 | B52: PRIMARY HEALTH CENTRE | C52: 6 | D52: Kurkunta | E52: 5 | F52: 3 | G52: 4 | H52: 0.01 | J52: =SUM(E52:I52) -> 12.01
A53: 50 | B53: PRIMARY HEALTH CENTRE | C53: 6 | D53: Madana | E53: 6 | F53: 2 | G53: 5 | H53: 0.01 | J53: =SUM(E53:I53) -> 13.01
A54: 51 | B54: Primary Health Centre | C54: 6 | D54: Yadga | E54: 5 | F54: 1 | G54: 4 | H54: 0.01 | J54: =SUM(E54:I54) -> 10.01
A55: 52 | B55: Urban Primary Health Centre | C55: 0 | D55: Sedam | E55: 1 | F55: 1 | G55: 1 | H55: 0.01 | J55: =SUM(E55:I55) -> 3.01
A56: 53 | B56: MCH Hospital | C56: 100 | D56: Kalaburagi | E56: 60 | F56: 22 | G56: 24 | H56: 0.9 | J56: =SUM(E56:I56) -> 106.9
A57: 54 | B57: Primary Health Centre | C57: 6 | D57: Farthabad | E57: 20 | F57: 4 | G57: 3 | H57: 0.01 | J57: =SUM(E57:I57) -> 27.01
A58: 55 | B58: Primary Health Centre | C58: 6 | D58: Hire Savalgi | E58: 6 | F58: 2 | G58: 3 | H58: 0.01 | J58: =SUM(E58:I58) -> 11.01
...

Sheet Jewargi
A1: Collection of Bio-Medical Waste from Jewargi Taluk, Kalaburagi Dist. in Category wise for the month of JUN-2026
A2: Sr.No | B2: Name Of Hospitals | D2: Quantity of Bio-medical Waste Received All in Kg/month | J2: GENERAL | K2: Total Qty in kg/month
D3: BED'S | E3: PLACE | F3: YELLOW | G3: RED | H3: BLUE | I3: WHITE
A4: 1 | B4: ADITYA CLINIC | C4: CL | E4: JEWARGI | F4: 3 | G4: 2 | H4: 2 | I4: 0.01 | K4: =SUM(F4:J4) -> 7.01
A5: 2 | B5: AL HAYAT CLINIC | C5: CL | E5: JEWARGI | F5: 3 | G5: 1 | H5: 2 | I5: 0.01 | J5: 5 | K5: =SUM(F5:J5) -> 11.01
A6: 3 | B6: AL SHIFA CLINIC | C6: CL | E6: JEWARGI | F6: 1 | G6: 1 | H6: 5 | I6: 0.01 | K6: =SUM(F6:J6) -> 7.01
A7: 4 | B7: AMOGHA HOSPITAL | C7: BH | D7: 6 | E7: JEWARGI | F7: 8 | G7: 3 | H7: 2 | I7: 0.02 | K7: =SUM(F7:J7) -> 13.02
A8: 5 | B8: ARJUN DENTAL AND IMPLANT CENTRE | C8: DC | E8: JEWARGI | F8: 1 | G8: 0.5 | H8: 0.5 | I8: 0.01 | K8: =SUM(F8:J8) -> 2.01
A9: 6 | B9: AROGYA HOSPITAL | C9: BH | D9: 5 | E9: JEWARGI | F9: 6 | G9: 2 | H9: 2 | I9: 0.02 | K9: =SUM(F9:J9) -> 10.02
A10: 7 | B10: BADAGHAR HEALTH CARE CLINIC | C10: CL | E10: JEWARGI | F10: 1 | G10: 2 | H10: 2 | I10: 0.01 | J10: 5 | K10: =SUM(F10:J10) -> 10.01
A11: 8 | B11: BANGALORE CLINIC | C11: CL | E11: JEWARGI | F11: 1 | G11: 1 | H11: 2 | I11: 0.01 | K11: =SUM(F11:J11) -> 4.01
A12: 9 | B12: BASAVA CLINIC | C12: CL | E12: JEWARGI | F12: 3 | G12: 1 | H12: 2 | I12: 0.01 | J12: 0 | K12: =SUM(F12:J12) -> 6.01
A13: 10 | B13: BASAVA CLINIC JEWARGI | C13: CL | E13: JEWARGI | F13: 1 | G13: 1 | H13: 2 | I13: 0.01 | K13: =SUM(F13:J13) -> 4.01
A14: 11 | B14: GANGOTRI MULTISPECIALITY HOSPITAL | C14: BH | D14: 20 | E14: YADRAMI | F14: 15 | G14: 16 | H14: 9 | I14: 0.5 | J14: 3 | K14: =SUM(F14:J14) -> 43.5
A15: 12 | B15: SADGURU SIDDAROODH SWAMY HOSPITAL | C15: BH | D15: 4 | E15: NELOGI | F15: 1 | G15: 1 | H15: 2 | I15: 0.01 | K15: =SUM(F15:J15) -> 4.01
A16: 13 | B16: BASAVA CLINIC KOLKUR | C16: CL | E16: JEWARGI | F16: 1 | G16: 1 | H16: 2 | I16: 0.01 | K16: =SUM(F16:J16) -> 4.01
A17: 14 | B17: BASAVA HOSPITAL | C17: BH | D17: 8 | E17: JEWARGI | F17: 4 | G17: 4 | H17: 2 | I17: 0.01 | J17: 5 | K17: =SUM(F17:J17) -> 15.01
A18: 15 | B18: BHAGYASHREE CLINIC | C18: CL | E18: JEWARGI | F18: 3 | G18: 1 | H18: 2 | I18: 0.01 | J18: 0 | K18: =SUM(F18:J18) -> 6.01
A19: 16 | B19: BHARAT CLINIC | C19: CL | E19: JEWARGI | F19: 2 | G19: 2 | H19: 1 | I19: 0.01 | K19: =SUM(F19:J19) -> 5.01
A20: 17 | B20: BIJAPUR LIFE CARE CLINIC | C20: CL | E20: JEWARGI | F20: 2 | G20: 2 | H20: 1 | I20: 0.01 | K20: =SUM(F20:J20) -> 5.01
A21: 18 | B21: BOMBAY CLINIC | C21: CL | E21: JEWARGI | F21: 2 | G21: 2 | H21: 2 | I21: 0.01 | K21: =SUM(F21:J21) -> 6.01
A22: 19 | B22: CHIRAG MS HOSPTIAL | C22: BH | D22: 25 | E22: JEWARGI | F22: 15 | G22: 16 | H22: 9 | I22: 0.5 | J22: 3 | K22: =SUM(F22:J22) -> 43.5
A23: 20 | B23: DEC Salt Project Karnataka | C23: LAB | E23: JEWARGI | F23: 2 | G23: 1 | I23: 0.01 | K23: =SUM(F23:J23) -> 3.01
A24: 21 | B24: DR. KK’S DENTAL SPACE | C24: DC | E24: JEWARGI | F24: 2 | G24: 0.5 | H24: 0.5 | I24: 0.01 | K24: =SUM(F24:J24) -> 3.01
A25: 22 | B25: EXPERT DIAGNOSTIC LABORATORY | C25: LAB | E25: JEWARGI | F25: 2 | G25: 1 | I25: 0.01 | K25: =SUM(F25:J25) -> 3.01
A26: 23 | B26: GOLA DENTAL CLINIC | C26: DC | E26: JEWARGI | F26: 2 | G26: 0.5 | H26: 0.5 | I26: 0.01 | K26: =SUM(F26:J26) -> 3.01
A27: 24 | B27: GOUDAR MATERNITY AND GENERAL HSOPITAL | C27: BH | D27: 6 | E27: JEWARGI | F27: 7 | G27: 4 | H27: 2 | I27: 0.02 | K27: =SUM(F27:J27) -> 13.02
A28: 25 | B28: JAKATI CHILDRENS HOSPITAL | C28: BH | D28: 10 | E28: JEWARGI | F28: 5 | G28: 3 | H28: 3 | I28: 0.01 | J28: 7 | K28: =SUM(F28:J28) -> 18.01
A29: 26 | B29: KALABURAGI LIFE CARE CLINIC | C29: CL | E29: JEWARGI | F29: 1 | G29: 1 | H29: 1 | I29: 0.01 | K29: =SUM(F29:J29) -> 3.01
A30: 27 | B30: LAXMI DIAGNOSTIC LABORATORY | C30: LAB | E30: JEWARGI | F30: 2 | G30: 2 | I30: 0.01 | K30: =SUM(F30:J30) -> 4.01
A31: 28 | B31: LIFE CLINIC | C31: CL | E31: JEWARGI | F31: 1 | G31: 2 | H31: 2 | I31: 0.01 | J31: 5 | K31: =SUM(F31:J31) -> 10.01
A32: 29 | B32: MAHALAXMI LAB JEWARGI | C32: LAB | E32: JEWARGI | F32: 2 | G32: 2 | I32: 0.01 | K32: =SUM(F32:J32) -> 4.01
A33: 30 | B33: MIRAJ MULTISPECIALITY HOSPITAL | C33: BH | D33: 12 | E33: JEWARGI | F33: 6 | G33: 3 | H33: 2 | I33: 0.4 | K33: =SUM(F33:J33) -> 11.4
A34: 31 | B34: NANDI DIAGNOSTIC LABORATORY | C34: LAB | E34: JEWARGI | F34: 3 | G34: 1 | I34: 0.01 | K34: =SUM(F34:J34) -> 4.01
A35: 32 | B35: NIRMALA DEVI CHILD AND MATERNITY CLINIC | C35: CL | E35: JEWARGI | F35: 1 | G35: 2 | H35: 2 | I35: 0.01 | J35: 0 | K35: =SUM(F35:J35) -> 5.01
A36: 33 | B36: NIRMALA HOSPITAL (CLINIC) | C36: CL | E36: JEWARGI | F36: 2 | G36: 2 | H36: 2 | I36: 0.01 | J36: 5 | K36: =SUM(F36:J36) -> 11.01
A37: 34 | B37: NOOLA CLINIC | C37: CL | E37: YADRAMI | F37: 3 | G37: 2 | H37: 3 | I37: 0.01 | K37: =SUM(F37:J37) -> 8.01
A38: 35 | B38: SHREE BASAVA CLINIC | C38: CL | E38: YADRAMI | F38: 2 | G38: 1 | H38: 2 | I38: 0.01 | K38: =SUM(F38:J38) -> 5.01
A39: 36 | B39: SHREE PARVATI CLINIC | C39: CL | E39: YADRAMI | F39: 3 | G39: 1 | H39: 2 | I39: 0.01 | K39: =SUM(F39:J39) -> 6.01
A40: 37 | B40: LALITA CLINIC | C40: CL | E40: YADRAMI | F40: 2 | G40: 2 | H40: 5 | I40: 0.01 | K40: =SUM(F40:J40) -> 9.01
...

Sheet Sedam
A1: Collection of Bio-Medical Waste from Sedam Taluk, Kalaburagi Dist. in Category wise for the month of JUN-2026
A2: Sr.No | B2: Name Of Hospitals | D2: Quantity of Bio-medical Waste Received All in Kg/month | J2: GENERAL | K2: Total Qty in kg/month
D3: BED'S | E3: PLACE | F3: YELLOW | G3: RED | H3: BLUE | I3: WHITE
A4: 1 | B4: AAROGYA DIAGNOSTIC CENTRE | C4: LAB | E4: SEDAM | F4: 2 | G4: 2 | I4: 0.01 | K4: =SUM(F4:J4) -> 4.01
A5: 2 | B5: AGNOOR CLINIC | C5: CL | E5: SEDAM | F5: 3 | G5: 1 | H5: 2 | I5: 0.01 | K5: =SUM(F5:J5) -> 6.01
A6: 3 | B6: AMMA CLINIC | C6: CL | E6: SEDAM | F6: 2 | G6: 2 | H6: 3 | I6: 0.01 | K6: =SUM(F6:J6) -> 7.01
A7: 4 | B7: AROGYA CLINIC | C7: CL | E7: SEDAM | F7: 2 | G7: 1 | H7: 3 | I7: 0.01 | K7: =SUM(F7:J7) -> 6.01
A8: 5 | B8: ASHWINI MULTISPECIALITY HOSPITAL | C8: BH | D8: 7 | E8: SEDAM | F8: 8 | G8: 4 | H8: 3 | I8: 0.02 | K8: =SUM(F8:J8) -> 15.02
A9: 6 | B9: AYUSH CLINIC | C9: CL | E9: SEDAM | F9: 4 | G9: 1 | H9: 2 | I9: 0.01 | J9: 0 | K9: =SUM(F9:J9) -> 7.01
A10: 7 | B10: BALABHEEMASENA CLINIC | C10: CL | E10: SEDAM | F10: 2 | G10: 1 | H10: 1 | I10: 0.01 | K10: =SUM(F10:J10) -> 4.01
A11: 8 | B11: BASAVA CLINIC SEDAM | C11: CL | E11: SEDAM | F11: 3 | G11: 2 | H11: 2 | I11: 0.01 | K11: =SUM(F11:J11) -> 7.01
A12: 9 | B12: CHIRAYU HOSPITAL SEDAM | C12: BH | D12: 8 | E12: SEDAM | F12: 8 | G12: 4 | H12: 3 | I12: 0.02 | K12: =SUM(F12:J12) -> 15.02
A13: 10 | B13: CHETAN CLINIC | C13: CL | E13: SEDAM | F13: 2 | G13: 2 | H13: 1 | I13: 0.01 | K13: =SUM(F13:J13) -> 5.01
A14: 11 | B14: DHANVANTRI OCCUPATIONAL HEALTH CENTER MALKHED | C14: BH | D14: 8 | E14: MALKHED | F14: 3 | G14: 2 | H14: 2 | I14: 0.01 | K14: =SUM(F14:J14) -> 7.01
A15: 12 | B15: DENTAL CLINIC | C15: DC | E15: SEDAM | F15: 2 | G15: 0.5 | H15: 0.5 | I15: 0.01 | K15: =SUM(F15:J15) -> 3.01
A16: 13 | B16: DR AZHAR CLINIC | C16: CL | E16: SEDAM | F16: 2 | G16: 1 | H16: 2 | I16: 0.01 | K16: =SUM(F16:J16) -> 5.01
A17: 14 | B17: DR VENKAT REDDY PATIL HOSPITAL | C17: BH | D17: 10 | E17: SEDAM | F17: 7 | G17: 3 | H17: 3 | I17: 0.2 | J17: 0 | K17: =SUM(F17:J17) -> 13.2
A18: 15 | B18: DR. SANGAVI HOSPITAL | C18: BH | D18: 5 | E18: SEDAM | F18: 8 | G18: 3 | H18: 2 | I18: 0.1 | K18: =SUM(F18:J18) -> 13.1
A19: 16 | B19: HEMAREDDY MALLAMMA MEDICAL CENTRE | C19: CL | E19: SEDAM | F19: 3 | G19: 1 | H19: 2 | I19: 0.01 | K19: =SUM(F19:J19) -> 6.01
A20: 17 | B20: HUMA MEDICAL CENTRE | C20: CL | E20: SEDAM | F20: 3 | G20: 1 | H20: 2 | I20: 0.01 | K20: =SUM(F20:J20) -> 6.01
A21: 18 | B21: KANKERIS KIDS CARE | C21: CL | E21: SEDAM | F21: 3 | G21: 1 | H21: 5 | I21: 0.01 | J21: 5 | K21: =SUM(F21:J21) -> 14.01
A22: 19 | B22: KOLLUR ORTHO CARE | C22: CL | E22: SEDAM | F22: 3 | G22: 1 | H22: 2 | I22: 0.01 | K22: =SUM(F22:J22) -> 6.01
A23: 20 | B23: MATRUCHAYA CLINIC | C23: CL | E23: SEDAM | F23: 2 | G23: 1 | H23: 2 | I23: 0.01 | K23: =SUM(F23:J23) -> 5.01
A24: 21 | B24: NISARGA MULTI CARE HOSPITAL | C24: BH | D24: 5 | E24: SEDAM | F24: 6 | G24: 3 | H24: 4 | I24: 0.01 | K24: =SUM(F24:J24) -> 13.01
A25: 22 | B25: OCCUPATIONAL HEALTH CENTRE SARAL NAGAR CEMENT WORKS | C25: BH | D25: 4 | E25: SEDAM | F25: 4 | G25: 2 | H25: 2 | I25: 0.01 | K25: =SUM(F25:J25) -> 8.01
A26: 23 | B26: PATIL MEDICAL CENTRE | C26: CL | E26: SEDAM | F26: 2 | G26: 1 | H26: 2 | I26: 0.01 | K26: =SUM(F26:J26) -> 5.01
A27: 24 | B27: RADHAKRISHNA HOSPITAL | C27: BH | D27: 10 | E27: SEDAM | F27: 8 | G27: 4 | H27: 2 | I27: 0.1 | J27: 0 | K27: =SUM(F27:J27) -> 14.1
A28: 25 | B28: RANJOLKAR HOSPITAL | C28: CL | E28: SEDAM | F28: 3 | G28: 2 | H28: 3 | I28: 0.01 | K28: =SUM(F28:J28) -> 8.01
A29: 26 | B29: REDDY HOSPITAL | C29: BH | D29: 10 | E29: SEDAM | F29: 10 | G29: 3 | H29: 3 | I29: 0.3 | J29: 5 | K29: =SUM(F29:J29) -> 21.3
A30: 27 | B30: SADASHIV HOSPITAL | C30: CL | E30: SEDAM | F30: 2 | G30: 2 | H30: 3 | I30: 0.01 | K30: =SUM(F30:J30) -> 7.01
A31: 28 | B31: SANJEEVINI CLINIC | C31: CL | E31: SEDAM | F31: 3 | G31: 1 | H31: 2 | I31: 0.01 | K31: =SUM(F31:J31) -> 6.01
A32: 29 | B32: SANJEEVINI CLINIC SEDAM | C32: CL | E32: SEDAM | F32: 2 | G32: 2 | H32: 2 | I32: 0.01 | K32: =SUM(F32:J32) -> 6.01
A33: 30 | B33: SARVODAYA HOSPITAL | C33: BH | D33: 15 | E33: SEDAM | F33: 12 | G33: 5 | H33: 2 | I33: 0.3 | J33: 15 | K33: =SUM(F33:J33) -> 34.3
A34: 31 | B34: SEDAM DANTALAYA | C34: DC | E34: SEDAM | F34: 2 | G34: 0.5 | H34: 0.5 | I34: 0.01 | K34: =SUM(F34:J34) -> 3.01
A35: 32 | B35: SEDAM DIAGNOSTIC LABORATORY | C35: LAB | E35: SEDAM | F35: 3 | G35: 2 | I35: 0.01 | K35: =SUM(F35:J35) -> 5.01
A36: 33 | B36: SEDAM HOSPITAL | C36: BH | D36: 15 | E36: SEDAM | F36: 13 | G36: 4 | H36: 3 | I36: 0.3 | J36: 8 | K36: =SUM(F36:J36) -> 28.3
A37: 34 | B37: AYUSH CHILDREN HOSPITAL | C37: CL | E37: MUDHOL | F37: 3 | G37: 1 | H37: 1 | I37: 0.01 | K37: =SUM(F37:J37) -> 5.01
A38: 35 | B38: DHANVANTRI CLINIC | C38: CL | E38: MUDHOL | F38: 4 | G38: 1 | H38: 2 | I38: 0.01 | K38: =SUM(F38:J38) -> 7.01
A39: 36 | B39: SANGAMESHWAR CLINIC | C39: CL | E39: MUDHOL | F39: 2 | G39: 2 | H39: 1 | I39: 0.01 | K39: =SUM(F39:J39) -> 5.01
A40: 37 | B40: SRI VENKATESHWAR CLINIC | C40: CL | E40: MUDHOL | F40: 2 | G40: 1 | H40: 1 | I40: 0.01 | K40: =SUM(F40:J40) -> 4.01
...

Sheet Chittapur
A1: Collection of Bio-Medical Waste from Chittapur Taluk, KalaburagiDist. in Category wise for the month of JUN-2026
A2: Sr.No | B2: Name Of Hospitals | D2: Quantity of Bio-medical Waste Received in Kg/month | J2: GENERAL | K2: Total Qty in kg/month
D3: BED'S | E3: PLACE | F3: YELLOW | G3: RED | H3: BLUE | I3: WHITE
A4: 1 | B4: DR OHM INDO-GERMAN HOSPITAL | C4: BH | D4: 12 | E4: CHITTAPUR | F4: 11 | G4: 4 | H4: 3 | I4: 0.2 | J4: 0 | K4: =SUM(F4:J4) -> 18.2
A5: 2 | B5: AL KAUASAR ORTHO MATERNITY AND MULTISPECIALITY HOSPITAL | C5: BH | D5: 6 | E5: CHITTAPUR | F5: 6 | G5: 4 | H5: 3 | I5: 0.1 | K5: =SUM(F5:J5) -> 13.1
A6: 3 | B6: SAI HOSPITAL | C6: BH | D6: 5 | E6: SHAHABAD | F6: 7 | G6: 3 | H6: 3 | I6: 0.1 | J6: 6 | K6: =SUM(F6:J6) -> 19.1
A7: 4 | B7: HANIYA HEALTH CARE MATERNITY AND GENERAL HOSPITAL | C7: BH | D7: 8 | E7: WADI | F7: 10 | G7: 2 | H7: 2 | I7: 0.1 | J7: 0 | K7: =SUM(F7:J7) -> 14.1
A8: 5 | B8: JEEVAN SEVA MATERNITY AND GENERAL HOSPITAL | C8: BH | D8: 8 | E8: WADI | F8: 9 | G8: 2 | H8: 3 | I8: 0.1 | K8: =SUM(F8:J8) -> 14.1
A9: 6 | B9: SHIFA HOSPITAL | C9: BH | D9: 6 | E9: WADI | F9: 8 | G9: 2 | H9: 2 | I9: 0.1 | K9: =SUM(F9:J9) -> 12.1
A10: 7 | B10: ASHWINI CLINIC | C10: CL | E10: CHITTAPUR | F10: 1 | G10: 1 | H10: 1 | I10: 0.01 | K10: =SUM(F10:J10) -> 3.01
A11: 8 | B11: ANSARI CLINIC | C11: CL | E11: NALWAR | F11: 1 | G11: 1 | H11: 1 | I11: 0.01 | K11: =SUM(F11:J11) -> 3.01
A12: 9 | B12: BALBATTI CLINIC | C12: CL | E12: CHITTAPUR | F12: 2 | G12: 1 | H12: 1 | I12: 0.01 | K12: =SUM(F12:J12) -> 4.01
A13: 10 | B13: BASAVA CLINIC, CHITTAPUR | C13: CL | E13: CHITTAPUR | F13: 3 | G13: 1 | H13: 1 | I13: 0.01 | K13: =SUM(F13:J13) -> 5.01
A14: 11 | B14: GIRI BASAVA CLINIC | C14: CL | E14: CHITTAPUR | F14: 2 | G14: 2 | H14: 1 | I14: 0.01 | K14: =SUM(F14:J14) -> 5.01
A15: 12 | B15: HAFEEZ CLINIC | C15: CL | E15: CHITTAPUR | F15: 2 | G15: 1 | H15: 1 | I15: 0.01 | K15: =SUM(F15:J15) -> 4.01
A16: 13 | B16: JAI BHAVANI MEDICAL CENTRE | C16: CL | E16: CHITTAPUR | F16: 2 | G16: 2 | H16: 2 | I16: 0.01 | K16: =SUM(F16:J16) -> 6.01
A17: 14 | B17: SMILE DWNTAL CLINIC | C17: CL | E17: SHAHABAD | F17: 2 | G17: 2 | H17: 1 | I17: 0.01 | K17: =SUM(F17:J17) -> 5.01
A18: 15 | B18: NEW ASIF POLY CLINIC | C18: CL | E18: CHITTAPUR | F18: 2 | G18: 1 | H18: 1 | I18: 0.01 | K18: =SUM(F18:J18) -> 4.01
A19: 16 | B19: SAPNA CLINIC | C19: CL | E19: CHITTAPUR | F19: 2 | G19: 2 | H19: 1 | I19: 0.01 | K19: =SUM(F19:J19) -> 5.01
A20: 17 | B20: SREE RAGHAVENDRA MEDICAL CENTRE | C20: CL | E20: CHITTAPUR | F20: 3 | G20: 1 | H20: 1 | I20: 0.01 | K20: =SUM(F20:J20) -> 5.01
A21: 18 | B21: TIKADAR CLINIC | C21: CL | E21: CHITTAPUR | F21: 2 | G21: 1 | H21: 1 | I21: 0.01 | K21: =SUM(F21:J21) -> 4.01
... A27: 24 | B27: DR V C. INGINSHETTY CLINIC | C27: CL | E27: SHAHABAD | F27: 2 | G27: 2 | H27: 1 | I27: 0.01 | K27: =SUM(F27:J27) -> 5.01
A28: 25 | B28: MATHWALI CLINIC | C28: CL | E28: SHAHABAD | F28: 3 | G28: 1 | H28: 1 | I28: 0.01 | J28: 6 | K28: =SUM(F28:J28) -> 11.01
A29: 26 | B29: NAVJEEVAN CLINIC | C29: CL | E29: SHAHABAD | F29: 2 | G29: 1 | H29: 2 | I29: 0.01 | K29: =SUM(F29:J29) -> 5.01
A30: 27 | B30: SANJEEV CLINIC | C30: CL | E30: SHAHABAD | F30: 3 | G30: 1 | H30: 1 | I30: 0.01 | K30: =SUM(F30:J30) -> 5.01
A31: 28 | B31: JADHAV CLINIC | C31: CL | E31: SHAHABAD | F31: 3 | G31: 1 | H31: 1 | I31: 0.01 | K31: =SUM(F31:J31) -> 5.01
A32: 29 | B32: AL NISA CLINIC | C32: CL | E32: WADI | F32: 2 | G32: 2 | H32: 1 | I32: 0.01 | K32: =SUM(F32:J32) -> 5.01
A33: 30 | B33: ANSARI CLINIC | C33: CL | E33: WADI | F33: 3 | G33: 1 | H33: 1 | I33: 0.01 | K33: =SUM(F33:J33) -> 5.01
A34: 31 | B34: PAWAR CLINIC | C34: CL | E34: WADI | F34: 3 | G34: 1 | H34: 2 | I34: 0.01 | K34: =SUM(F34:J34) -> 6.01
A35: 32 | B35: RAILWAY POLY CLINIC | C35: CL | E35: WADI | F35: 3 | G35: 2 | H35: 1 | I35: 0.01 | K35: =SUM(F35:J35) -> 6.01
A36: 33 | B36: SANJAY B MUNOLI CHILDRENS CLINIC | C36: CL | E36: WADI | F36: 3 | G36: 2 | H36: 2 | I36: 0.01 | J36: 5 | K36: =SUM(F36:J36) -> 12.01
A37: 34 | B37: SANJEEVINI CLINIC | C37: CL | E37: WADI | F37: 2 | G37: 1 | H37: 1 | I37: 0.01 | K37: =SUM(F37:J37) -> 4.01
A38: 35 | B38: VEERESH CLINIC | C38: CL | E38: WADI | F38: 3 | G38: 1 | H38: 2 | I38: 0.01 | K38: =SUM(F38:J38) -> 6.01
A39: 36 | B39: VIKAS CLINIC, WADI | C39: CL | E39: WADI | F39: 2 | G39: 3 | H39: 1 | I39: 0.01 | K39: =SUM(F39:J39) -> 6.01
A40: 37 | B40: VIKAS SPECIALITY HEALTH CARE CLINIC | C40: CL | E40: WADI | F40: 2 | G40: 1 | H40: 2 | I40: 0.01 | J40: 5 | K40: =SUM(F40:J40) -> 10.01
A41: 38 | B41: UNIVERSAL CLINIC, | C41: CL | E41: WADI | F41: 2 | G41: 1 | H41: 2 | I41: 0.01 | K41: =SUM(F41:J41) -> 5.01
A42: 39 | B42: S K CHAVAN PHYSIOTHERAPY CENTRE | C42: CL | E42: Kalagi | F42: 3 | G42: 1 | H42: 2 | I42: 0.01 | K42: =SUM(F42:J42) -> 6.01
A43: 40 | B43: SOLAPUR CLINIC | C43: CL | E43: Kalagi | F43: 2 | G43: 1 | H43: 2 | I43: 0.01 | K43: =SUM(F43:J43) -> 5.01
A44: 41 | B44: NIJAMUDDIN DENTAL CLINIC | C44: DC | E44: CHITTAPUR | F44: 0.5 | G44: 0.5 | H44: 0.5 | I44: 0.01 | K44: =SUM(F44:J44) -> 1.51
A45: 42 | B45: TAMANNA DENTAL CLINIC | C45: DC | E45: CHITTAPUR | F45: 1 | G45: 0.5 | H45: 0.5 | I45: 0.01 | K45: =SUM(F45:J45) -> 2.01
...

Sheet Kalaburagi
A1: Collection of Bio-Medical Waste from Kalaburagi City, Kalaburagi Dist. in Category wise for the month of JUN-2026
A2: Sr.No | B2: Name Of Hospitals | D2: Quantity of Bio-medical Waste Received All in Kg/month | J2: GENERAL | K2: Total Qty in kg/month
D3: BED'S | E3: PLACE | F3: YELLOW | G3: RED | H3: BLUE | I3: WHITE
A4: 1 | B4: 32 PERARLS DENTAL SPECIALITIES | C4: DC | E4: KALABURAGI | F4: 3 | G4: 1 | H4: 0.5 | I4: 0.1 | J4: 0 | K4: =SUM(F4:J4) -> 4.6
A5: 2 | B5: A J CLINIC | C5: CL | E5: KALABURAGI | F5: 2 | G5: 1 | H5: 3 | I5: 0.1 | J5: 0 | K5: =SUM(F5:J5) -> 6.1
A6: 3 | B6: ADITI HOSPITAL | C6: BH | D6: 30 | E6: KALABURAGI | F6: 38 | G6: 16 | H6: 6 | I6: 0.58 | J6: 0 | K6: =SUM(F6:J6) -> 60.58
A7: 4 | B7: ADITYA MULTI SPECIALITY HOSPITAL | C7: BH | D7: 30 | E7: KALABURAGI | F7: 26 | G7: 16 | H7: 8 | I7: 0.6 | J7: 0 | K7: =SUM(F7:J7) -> 50.6
A8: 5 | B8: AISHA MATERNITY AND GENERAL HOSPITAL | C8: BH | D8: 20 | E8: KALABURAGI | F8: 38 | G8: 17 | H8: 5 | I8: 0.4 | J8: 5 | K8: =SUM(F8:J8) -> 65.4
A9: 6 | B9: ALASHETTY SPECIALITY CLINIC | C9: CL | E9: KALABURAGI | F9: 2 | G9: 0.5 | H9: 1 | I9: 0.1 | J9: 0 | K9: =SUM(F9:J9) -> 3.6
A10: 7 | B10: AL-BADAR DENTAL COLLEGE | C10: BH | D10: 20 | E10: KALABURAGI | F10: 18 | G10: 11 | H10: 6 | I10: 0.5 | J10: 4 | K10: =SUM(F10:J10) -> 39.5
A11: 8 | B11: AMRUTA SPARSH HOSPITAL | C11: BH | D11: 28 | E11: KALABURAGI | F11: 22 | G11: 18 | H11: 5 | I11: 0.6 | J11: 6 | K11: =SUM(F11:J11) -> 51.6
A12: 9 | B12: AMRUTHRATNA NEURO HOSPITAL | C12: BH | D12: 15 | E12: KALABURAGI | F12: 14 | G12: 11 | H12: 5 | I12: 0.2 | J12: 3 | K12: =SUM(F12:J12) -> 33.2
A13: 10 | B13: ANGEL CHILDRENS HOSPITAL | C13: BH | D13: 13 | E13: KALABURAGI | F13: 9 | G13: 7 | H13: 3 | I13: 0.3 | J13: 0 | K13: =SUM(F13:J13) -> 19.3
A14: 11 | B14: ANITA SCANNING CENTRE | C14: SC | E14: KALABURAGI | F14: 1 | G14: 4 | I14: 0.1 | J14: 0 | K14: =SUM(F14:J14) -> 5.1
A15: 12 | B15: APEX DENTAL CLINIC | C15: DC | E15: KALABURAGI | F15: 2 | G15: 0.1 | H15: 0.5 | I15: 0.1 | J15: 0 | K15: =SUM(F15:J15) -> 2.7
A16: 13 | B16: APEX SURGICAL AND GENERAL CARE HOSPITAL | C16: BH | D16: 4 | E16: KALABURAGI | F16: 10 | G16: 6 | H16: 2 | I16: 0.2 | J16: 4 | K16: =SUM(F16:J16) -> 22.2
A17: 14 | B17: ARKA DIAGNOSTIC AND SCANNING CENTRE | C17: SC | E17: KALABURAGI | F17: 3 | G17: 3 | I17: 0.1 | J17: 0 | K17: =SUM(F17:J17) -> 6.1
A18: 15 | B18: AROGYA LIFE CARE MULTISPECIALITY HOSPITAL | C18: BH | D18: 29 | E18: KALABURAGI | F18: 18 | G18: 18 | H18: 4 | I18: 0.6 | J18: 5 | K18: =SUM(F18:J18) -> 45.6
A19: 16 | B19: ARUJIVA AYURVEDA HOSPITAL | C19: BH | D19: 28 | E19: KALABURAGI | F19: 24 | G19: 13 | H19: 5 | I19: 0.5 | J19: 5 | K19: =SUM(F19:J19) -> 47.5
A20: 17 | B20: ASHIRWAD METERNITY AND CHILDREN HOSPITAL | C20: BH | D20: 20 | E20: KALABURAGI | F20: 22 | G20: 13 | H20: 6 | I20: 0.4 | J20: 3 | K20: =SUM(F20:J20) -> 44.4
A21: 18 | B21: ASHWINI CLINIC | C21: CL | E21: KALABURAGI | F21: 3 | G21: 2 | H21: 2 | I21: 0.1 | J21: 0 | K21: =SUM(F21:J21) -> 7.1
A22: 19 | B22: ATHARVA CHEST HOSPITAL | C22: BH | D22: 15 | E22: KALABURAGI | F22: 8 | G22: 9 | H22: 4 | I22: 0.3 | J22: 4 | K22: =SUM(F22:J22) -> 25.3
A23: 20 | B23: ATHARVA CLINIC | C23: CL | E23: KALABURAGI | F23: 3 | G23: 0 | H23: 1 | I23: 0.1 | J23: 0 | K23: =SUM(F23:J23) -> 4.1
A24: 21 | B24: AVATIS PUSHKAR HOSPITAL | C24: BH | D24: 30 | E24: KALABURAGI | F24: 18 | G24: 19 | H24: 6 | I24: 0.5 | J24: 5 | K24: =SUM(F24:J24) -> 48.5
A25: 22 | B25: AYU CLINIC | C25: CL | E25: KALABURAGI | F25: 1 | G25: 1 | H25: 2 | I25: 0.1 | J25: 3 | K25: =SUM(F25:J25) -> 7.1
A26: 23 | B26: BABAHOUSE DIAGNOSTIC CENTRE | C26: Lab | E26: KALABURAGI | F26: 2 | G26: 3 | I26: 0.1 | J26: 0 | K26: =SUM(F26:J26) -> 5.1
A27: 24 | B27: BALABATTI SKIN, HAIR AND NAIL CLINIC | C27: CL | E27: KALABURAGI | F27: 2 | G27: 3 | H27: 2 | I27: 0.1 | J27: 0 | K27: =SUM(F27:J27) -> 7.1
A28: 25 | B28: BALAJI HOSPITAL | C28: BH | D28: 18 | E28: KALABURAGI | F28: 19 | G28: 18 | H28: 9 | I28: 0.2 | J28: 3 | K28: =SUM(F28:J28) -> 49.2
A29: 26 | B29: BANALE HOSPITAL | C29: BH | D29: 30 | E29: KALABURAGI | F29: 21 | G29: 14 | H29: 5 | I29: 0.6 | J29: 0 | K29: =SUM(F29:J29) -> 40.6
A30: 27 | B30: BANASHANKARI MATERNITY HOME | C30: BH | D30: 10 | E30: KALABURAGI | F30: 10 | G30: 8 | H30: 9 | I30: 0.2 | J30: 5 | K30: =SUM(F30:J30) -> 32.2
A31: 28 | B31: BANKUR MULTISPECIALITY DENTAL CLINIC | C31: DC | E31: KALABURAGI | F31: 2 | G31: 0.2 | H31: 0.2 | I31: 0.1 | J31: 0 | K31: =SUM(F31:J31) -> 2.5
A32: 29 | B32: BAOGI HOSPITAL | C32: BH | D32: 7 | E32: KALABURAGI | F32: 14 | G32: 6 | H32: . | I32: 0.2 | J32: 5 | K32: =SUM(F32:J32) -> 25.2
A33: 30 | B33: BASAVA HOSPITAL | C33: CL | E33: KALABURAGI | F33: 2 | G33: 2 | H33: 3 | I33: 0.1 | J33: 0 | K33: =SUM(F33:J33) -> 7.1
A34: 31 | B34: BASAVA NURSING HOME | C34: BH | D34: 4 | E34: KALABURAGI | F34: 10 | G34: 2 | H34: 1 | I34: 0.2 | J34: 4 | K34: =SUM(F34:J34) -> 17.2
A35: 32 | B35: BASAVACHETANA MATERNITY AND FERTILITY HOME | C35: BH | D35: 20 | E35: KALABURAGI | F35: 26 | G35: 14 | H35: 5 | I35: 0.4 | J35: 5 | K35: =SUM(F35:J35) -> 50.4
A36: 33 | B36: BASAVESHWAR TEACHING AND GENERAL HOSPITAL | C36: BH | D36: 600 | E36: KALABURAGI | F36: 845 | G36: 430 | H36: 90 | I36: 0.9 | J36: 0 | K36: =SUM(F36:J36) -> 1365.9
A37: 34 | B37: BHAVANI CLINIC | C37: CL | E37: KALABURAGI | F37: 2 | G37: 3 | H37: 2 | I37: 0.1 | J37: 0 | K37: =SUM(F37:J37) -> 7.1
A38: 35 | B38: BHANGARI HOSPITAL | C38: BH | D38: 5 | E38: KALABURAGI | F38: 6 | G38: 4 | H38: 2 | I38: 0.5 | J38: 5 | K38: =SUM(F38:J38) -> 17.5
A39: 36 | B39: BHORUKA NETRALAYA | C39: BH | D39: 30 | E39: KALABURAGI | F39: 10 | G39: 19 | H39: 6 | I39: 0.5 | J39: 0 | K39: =SUM(F39:J39) -> 35.5
A40: 37 | B40: BILVA HOSPITAL | C40: BH | D40: 30 | E40: KALABURAGI | F40: 32 | G40: 18 | H40: 8 | I40: 0.4 | J40: 0 | K40: =SUM(F40:J40) -> 58.4
...
